Traceback (most recent call last):
  File "/mnt/fast/nobackup/users/ae01116/multi-modal-dissertation-uos/test.py", line 330, in <module>
    main()
  File "/mnt/fast/nobackup/users/ae01116/multi-modal-dissertation-uos/test.py", line 152, in main
    cfg = mmcv.Config.fromfile(args.config)
  File "/mnt/fast/nobackup/users/ae01116/multi-modal-dissertation-uos/zegenv/lib/python3.9/site-packages/mmcv/utils/config.py", line 334, in fromfile
    cfg_dict, cfg_text = Config._file2dict(filename,
  File "/mnt/fast/nobackup/users/ae01116/multi-modal-dissertation-uos/zegenv/lib/python3.9/site-packages/mmcv/utils/config.py", line 248, in _file2dict
    _cfg_dict, _cfg_text = Config._file2dict(osp.join(cfg_dir, f))
  File "/mnt/fast/nobackup/users/ae01116/multi-modal-dissertation-uos/zegenv/lib/python3.9/site-packages/mmcv/utils/config.py", line 181, in _file2dict
    check_file_exist(filename)
  File "/mnt/fast/nobackup/users/ae01116/multi-modal-dissertation-uos/zegenv/lib/python3.9/site-packages/mmcv/utils/path.py", line 23, in check_file_exist
    raise FileNotFoundError(msg_tmpl.format(filename))
FileNotFoundError: file "/mnt/fast/nobackup/users/ae01116/multi-modal-dissertation-uos/configs/_base_/models/inner_zegclip.py" does not exist
