/mnt/fast/nobackup/scratch4weeks/ae01116/zegenv/lib/python3.9/site-packages/torch/distributed/launch.py:178: FutureWarning: The module torch.distributed.launch is deprecated
and will be removed in future. Use torchrun.
Note that --use_env is set by default in torchrun.
If your script expects `--local_rank` argument to be set, please
change it to read from `os.environ['LOCAL_RANK']` instead. See 
https://pytorch.org/docs/stable/distributed.html#launch-utility for 
further instructions

  warnings.warn(
[i 0721 11:42:15.474189 80 compiler.py:956] Jittor(1.3.8.5) src: /mnt/fast/nobackup/scratch4weeks/ae01116/zegenv/lib/python3.9/site-packages/jittor
[i 0721 11:42:15.501645 80 compiler.py:957] g++ at /usr/bin/g++(7.5.0)
[i 0721 11:42:15.501722 80 compiler.py:958] cache_path: /user/HS400/ae01116/.cache/jittor/jt1.3.8/g++7.5.0/py3.9.19/Linux-4.18.0-4x8b/AMDEPYC753232-x73/default
[i 0721 11:42:15.530190 80 __init__.py:411] Found nvcc(11.0.221) at /usr/local/cuda/bin/nvcc.
[i 0721 11:42:15.557747 80 __init__.py:411] Found addr2line(2.30) at /usr/bin/addr2line.
[i 0721 11:42:15.763434 80 compiler.py:1011] cuda key:cu11.0.221_sm_86
[i 0721 11:42:16.524086 80 __init__.py:227] Total mem: 503.74GB, using 16 procs for compiling.
[i 0721 11:42:17.237664 80 jit_compiler.cc:28] Load cc_path: /usr/bin/g++
[i 0721 11:42:21.916543 80 init.cc:62] Found cuda archs: [86,]
[w 0721 11:42:22.017382 80 compiler.py:1384] CUDA arch(86)>80 will be backward-compatible
[i 0721 11:42:22.148447 80 __init__.py:411] Found mpicc(2.1.1) at /usr/bin/mpicc.
[i 0721 11:42:22.675740 64 compiler.py:956] Jittor(1.3.8.5) src: /mnt/fast/nobackup/scratch4weeks/ae01116/zegenv/lib/python3.9/site-packages/jittor
[i 0721 11:42:22.709829 64 compiler.py:957] g++ at /usr/bin/g++(7.5.0)
[i 0721 11:42:22.709909 64 compiler.py:958] cache_path: /user/HS400/ae01116/.cache/jittor/jt1.3.8/g++7.5.0/py3.9.19/Linux-4.18.0-4x8b/AMDEPYC753232-x73/default
[i 0721 11:42:22.739111 64 __init__.py:411] Found nvcc(11.0.221) at /usr/local/cuda/bin/nvcc.
[i 0721 11:42:22.767834 64 __init__.py:411] Found addr2line(2.30) at /usr/bin/addr2line.
[i 0721 11:42:22.970711 64 compiler.py:1011] cuda key:cu11.0.221_sm_86
[i 0721 11:42:23.524489 64 __init__.py:227] Total mem: 503.74GB, using 16 procs for compiling.
[i 0721 11:42:23.903008 64 jit_compiler.cc:28] Load cc_path: /usr/bin/g++
[i 0721 11:42:27.174746 64 init.cc:62] Found cuda archs: [86,]
[w 0721 11:42:27.302358 64 compiler.py:1384] CUDA arch(86)>80 will be backward-compatible
[i 0721 11:42:27.440779 64 __init__.py:411] Found mpicc(2.1.1) at /usr/bin/mpicc.
[i 0721 11:42:28.018652 56 compiler.py:956] Jittor(1.3.8.5) src: /mnt/fast/nobackup/scratch4weeks/ae01116/zegenv/lib/python3.9/site-packages/jittor
[i 0721 11:42:28.053832 56 compiler.py:957] g++ at /usr/bin/g++(7.5.0)
[i 0721 11:42:28.053930 56 compiler.py:958] cache_path: /user/HS400/ae01116/.cache/jittor/jt1.3.8/g++7.5.0/py3.9.19/Linux-4.18.0-4x8b/AMDEPYC753232-x73/default
[i 0721 11:42:28.090265 56 __init__.py:411] Found nvcc(11.0.221) at /usr/local/cuda/bin/nvcc.
[i 0721 11:42:28.125965 56 __init__.py:411] Found addr2line(2.30) at /usr/bin/addr2line.
[i 0721 11:42:28.346276 56 compiler.py:1011] cuda key:cu11.0.221_sm_86
[i 0721 11:42:28.927774 56 __init__.py:227] Total mem: 503.74GB, using 16 procs for compiling.
[i 0721 11:42:29.322984 56 jit_compiler.cc:28] Load cc_path: /usr/bin/g++
[i 0721 11:42:32.476292 56 init.cc:62] Found cuda archs: [86,]
[w 0721 11:42:32.568879 56 compiler.py:1384] CUDA arch(86)>80 will be backward-compatible
[i 0721 11:42:32.684578 56 __init__.py:411] Found mpicc(2.1.1) at /usr/bin/mpicc.
[i 0721 11:42:33.162748 20 compiler.py:956] Jittor(1.3.8.5) src: /mnt/fast/nobackup/scratch4weeks/ae01116/zegenv/lib/python3.9/site-packages/jittor
[i 0721 11:42:33.193566 20 compiler.py:957] g++ at /usr/bin/g++(7.5.0)
[i 0721 11:42:33.193645 20 compiler.py:958] cache_path: /user/HS400/ae01116/.cache/jittor/jt1.3.8/g++7.5.0/py3.9.19/Linux-4.18.0-4x8b/AMDEPYC753232-x73/default
[i 0721 11:42:33.226919 20 __init__.py:411] Found nvcc(11.0.221) at /usr/local/cuda/bin/nvcc.
[i 0721 11:42:33.263180 20 __init__.py:411] Found addr2line(2.30) at /usr/bin/addr2line.
[i 0721 11:42:33.480884 20 compiler.py:1011] cuda key:cu11.0.221_sm_86
[i 0721 11:42:34.099538 20 __init__.py:227] Total mem: 503.74GB, using 16 procs for compiling.
[i 0721 11:42:34.463913 20 jit_compiler.cc:28] Load cc_path: /usr/bin/g++
[i 0721 11:42:37.603318 20 init.cc:62] Found cuda archs: [86,]
[w 0721 11:42:37.700058 20 compiler.py:1384] CUDA arch(86)>80 will be backward-compatible
[i 0721 11:42:37.796248 20 __init__.py:411] Found mpicc(2.1.1) at /usr/bin/mpicc.
Traceback (most recent call last):
  File "/mnt/fast/nobackup/users/ae01116/multi-modal-dissertation-uos/train.py", line 15, in <module>
    import models
  File "/mnt/fast/nobackup/users/ae01116/multi-modal-dissertation-uos/models/__init__.py", line 10, in <module>
    from models.segmentor.clip_rc import CLIPRC
  File "/mnt/fast/nobackup/users/ae01116/multi-modal-dissertation-uos/models/segmentor/clip_rc.py", line 8, in <module>
    from .encoder_decoder import EncoderDecoder
  File "/mnt/fast/nobackup/users/ae01116/multi-modal-dissertation-uos/models/segmentor/encoder_decoder.py", line 11, in <module>
    class EncoderDecoder(BaseSegmentor):
  File "/mnt/fast/nobackup/users/ae01116/multi-modal-dissertation-uos/jseg/utils/registry.py", line 10, in _register_module
    assert key not in self._modules, f"{key} is already registered."
Traceback (most recent call last):
AssertionError: EncoderDecoder is already registered.
  File "/mnt/fast/nobackup/users/ae01116/multi-modal-dissertation-uos/train.py", line 15, in <module>
    import models
  File "/mnt/fast/nobackup/users/ae01116/multi-modal-dissertation-uos/models/__init__.py", line 10, in <module>
    from models.segmentor.clip_rc import CLIPRC
  File "/mnt/fast/nobackup/users/ae01116/multi-modal-dissertation-uos/models/segmentor/clip_rc.py", line 8, in <module>
    from .encoder_decoder import EncoderDecoder
  File "/mnt/fast/nobackup/users/ae01116/multi-modal-dissertation-uos/models/segmentor/encoder_decoder.py", line 11, in <module>
    class EncoderDecoder(BaseSegmentor):
  File "/mnt/fast/nobackup/users/ae01116/multi-modal-dissertation-uos/jseg/utils/registry.py", line 10, in _register_module
    assert key not in self._modules, f"{key} is already registered."
AssertionError: EncoderDecoder is already registered.
Traceback (most recent call last):
  File "/mnt/fast/nobackup/users/ae01116/multi-modal-dissertation-uos/train.py", line 15, in <module>
    import models
  File "/mnt/fast/nobackup/users/ae01116/multi-modal-dissertation-uos/models/__init__.py", line 10, in <module>
    from models.segmentor.clip_rc import CLIPRC
  File "/mnt/fast/nobackup/users/ae01116/multi-modal-dissertation-uos/models/segmentor/clip_rc.py", line 8, in <module>
    from .encoder_decoder import EncoderDecoder
  File "/mnt/fast/nobackup/users/ae01116/multi-modal-dissertation-uos/models/segmentor/encoder_decoder.py", line 11, in <module>
    class EncoderDecoder(BaseSegmentor):
  File "/mnt/fast/nobackup/users/ae01116/multi-modal-dissertation-uos/jseg/utils/registry.py", line 10, in _register_module
    assert key not in self._modules, f"{key} is already registered."
AssertionError: EncoderDecoder is already registered.
Traceback (most recent call last):
  File "/mnt/fast/nobackup/users/ae01116/multi-modal-dissertation-uos/train.py", line 15, in <module>
    import models
  File "/mnt/fast/nobackup/users/ae01116/multi-modal-dissertation-uos/models/__init__.py", line 10, in <module>
    from models.segmentor.clip_rc import CLIPRC
  File "/mnt/fast/nobackup/users/ae01116/multi-modal-dissertation-uos/models/segmentor/clip_rc.py", line 8, in <module>
    from .encoder_decoder import EncoderDecoder
  File "/mnt/fast/nobackup/users/ae01116/multi-modal-dissertation-uos/models/segmentor/encoder_decoder.py", line 11, in <module>
    class EncoderDecoder(BaseSegmentor):
  File "/mnt/fast/nobackup/users/ae01116/multi-modal-dissertation-uos/jseg/utils/registry.py", line 10, in _register_module
    assert key not in self._modules, f"{key} is already registered."
AssertionError: EncoderDecoder is already registered.
ERROR:torch.distributed.elastic.multiprocessing.api:failed (exitcode: 1) local_rank: 0 (pid: 26) of binary: /mnt/fast/nobackup/scratch4weeks/ae01116/zegenv/bin/python
Traceback (most recent call last):
  File "/mnt/fast/nobackup/scratch4weeks/ae01116/zegenv/lib/python3.9/runpy.py", line 197, in _run_module_as_main
    return _run_code(code, main_globals, None,
  File "/mnt/fast/nobackup/scratch4weeks/ae01116/zegenv/lib/python3.9/runpy.py", line 87, in _run_code
    exec(code, run_globals)
  File "/mnt/fast/nobackup/scratch4weeks/ae01116/zegenv/lib/python3.9/site-packages/torch/distributed/launch.py", line 193, in <module>
    main()
  File "/mnt/fast/nobackup/scratch4weeks/ae01116/zegenv/lib/python3.9/site-packages/torch/distributed/launch.py", line 189, in main
    launch(args)
  File "/mnt/fast/nobackup/scratch4weeks/ae01116/zegenv/lib/python3.9/site-packages/torch/distributed/launch.py", line 174, in launch
    run(args)
  File "/mnt/fast/nobackup/scratch4weeks/ae01116/zegenv/lib/python3.9/site-packages/torch/distributed/run.py", line 710, in run
    elastic_launch(
  File "/mnt/fast/nobackup/scratch4weeks/ae01116/zegenv/lib/python3.9/site-packages/torch/distributed/launcher/api.py", line 131, in __call__
    return launch_agent(self._config, self._entrypoint, list(args))
  File "/mnt/fast/nobackup/scratch4weeks/ae01116/zegenv/lib/python3.9/site-packages/torch/distributed/launcher/api.py", line 259, in launch_agent
    raise ChildFailedError(
torch.distributed.elastic.multiprocessing.errors.ChildFailedError: 
============================================================
/mnt/fast/nobackup/users/ae01116/multi-modal-dissertation-uos/train.py FAILED
------------------------------------------------------------
Failures:
[1]:
  time      : 2024-07-21_11:42:44
  host      : ae01116-176633.0-aisurrey15.surrey.ac.uk
  rank      : 1 (local_rank: 1)
  exitcode  : 1 (pid: 27)
  error_file: <N/A>
  traceback : To enable traceback see: https://pytorch.org/docs/stable/elastic/errors.html
[2]:
  time      : 2024-07-21_11:42:44
  host      : ae01116-176633.0-aisurrey15.surrey.ac.uk
  rank      : 2 (local_rank: 2)
  exitcode  : 1 (pid: 28)
  error_file: <N/A>
  traceback : To enable traceback see: https://pytorch.org/docs/stable/elastic/errors.html
[3]:
  time      : 2024-07-21_11:42:44
  host      : ae01116-176633.0-aisurrey15.surrey.ac.uk
  rank      : 3 (local_rank: 3)
  exitcode  : 1 (pid: 29)
  error_file: <N/A>
  traceback : To enable traceback see: https://pytorch.org/docs/stable/elastic/errors.html
------------------------------------------------------------
Root Cause (first observed failure):
[0]:
  time      : 2024-07-21_11:42:44
  host      : ae01116-176633.0-aisurrey15.surrey.ac.uk
  rank      : 0 (local_rank: 0)
  exitcode  : 1 (pid: 26)
  error_file: <N/A>
  traceback : To enable traceback see: https://pytorch.org/docs/stable/elastic/errors.html
============================================================
