/mnt/fast/nobackup/scratch4weeks/ae01116/zegenv/lib/python3.9/site-packages/torch/distributed/launch.py:178: FutureWarning: The module torch.distributed.launch is deprecated
and will be removed in future. Use torchrun.
Note that --use_env is set by default in torchrun.
If your script expects `--local_rank` argument to be set, please
change it to read from `os.environ['LOCAL_RANK']` instead. See 
https://pytorch.org/docs/stable/distributed.html#launch-utility for 
further instructions

  warnings.warn(
[i 0728 14:02:19.085689 08 __init__.py:227] Total mem: 503.74GB, using 16 procs for compiling.
[i 0728 14:02:37.408967 08 jit_compiler.cc:28] Load cc_path: /usr/bin/g++
[i 0728 14:02:37.604832 08 init.cc:62] Found cuda archs: [86,]
[w 0728 14:02:37.677885 08 compiler.py:1384] CUDA arch(86)>80 will be backward-compatible
[i 0728 14:02:38.693082 08 __init__.py:411] Found mpicc(2.1.1) at /usr/bin/mpicc.
[i 0728 14:02:38.778658 08 compiler.py:34] Create cache dir: /user/HS400/ae01116/.cache/jittor/jt1.3.8/g++7.5.0/py3.9.19/Linux-4.18.0-4xae/AMDEPYC753232-x73/default/cu11.0.221_sm_86/custom_ops
[i 0728 14:02:40.582318 36 compiler.py:956] Jittor(1.3.8.5) src: /mnt/fast/nobackup/scratch4weeks/ae01116/zegenv/lib/python3.9/site-packages/jittor
[i 0728 14:02:40.586954 36 compiler.py:957] g++ at /usr/bin/g++(7.5.0)
[i 0728 14:02:40.587029 36 compiler.py:958] cache_path: /user/HS400/ae01116/.cache/jittor/jt1.3.8/g++7.5.0/py3.9.19/Linux-4.18.0-4xae/AMDEPYC753232-x73/default
[i 0728 14:02:40.593213 36 __init__.py:411] Found nvcc(11.0.221) at /usr/local/cuda/bin/nvcc.
[i 0728 14:02:40.599397 36 __init__.py:411] Found addr2line(2.30) at /usr/bin/addr2line.
[i 0728 14:02:40.752712 36 compiler.py:1011] cuda key:cu11.0.221_sm_86
[i 0728 14:02:41.230901 36 __init__.py:227] Total mem: 503.74GB, using 16 procs for compiling.
[i 0728 14:02:41.421310 36 jit_compiler.cc:28] Load cc_path: /usr/bin/g++
[i 0728 14:02:41.541197 36 init.cc:62] Found cuda archs: [86,]
[w 0728 14:02:41.616342 36 compiler.py:1384] CUDA arch(86)>80 will be backward-compatible
[i 0728 14:02:42.751202 36 __init__.py:411] Found mpicc(2.1.1) at /usr/bin/mpicc.
[i 0728 14:02:42.931023 48 compiler.py:956] Jittor(1.3.8.5) src: /mnt/fast/nobackup/scratch4weeks/ae01116/zegenv/lib/python3.9/site-packages/jittor
[i 0728 14:02:42.935605 48 compiler.py:957] g++ at /usr/bin/g++(7.5.0)
[i 0728 14:02:42.935677 48 compiler.py:958] cache_path: /user/HS400/ae01116/.cache/jittor/jt1.3.8/g++7.5.0/py3.9.19/Linux-4.18.0-4xae/AMDEPYC753232-x73/default
[i 0728 14:02:42.941531 48 __init__.py:411] Found nvcc(11.0.221) at /usr/local/cuda/bin/nvcc.
[i 0728 14:02:42.947291 48 __init__.py:411] Found addr2line(2.30) at /usr/bin/addr2line.
[i 0728 14:02:43.084566 48 compiler.py:1011] cuda key:cu11.0.221_sm_86
[i 0728 14:02:43.549439 48 __init__.py:227] Total mem: 503.74GB, using 16 procs for compiling.
[i 0728 14:02:43.713405 48 jit_compiler.cc:28] Load cc_path: /usr/bin/g++
[i 0728 14:02:43.848428 48 init.cc:62] Found cuda archs: [86,]
[w 0728 14:02:43.920068 48 compiler.py:1384] CUDA arch(86)>80 will be backward-compatible
[i 0728 14:02:44.940860 48 __init__.py:411] Found mpicc(2.1.1) at /usr/bin/mpicc.
[i 0728 14:02:45.125834 52 compiler.py:956] Jittor(1.3.8.5) src: /mnt/fast/nobackup/scratch4weeks/ae01116/zegenv/lib/python3.9/site-packages/jittor
[i 0728 14:02:45.131835 52 compiler.py:957] g++ at /usr/bin/g++(7.5.0)
[i 0728 14:02:45.131910 52 compiler.py:958] cache_path: /user/HS400/ae01116/.cache/jittor/jt1.3.8/g++7.5.0/py3.9.19/Linux-4.18.0-4xae/AMDEPYC753232-x73/default
[i 0728 14:02:45.138786 52 __init__.py:411] Found nvcc(11.0.221) at /usr/local/cuda/bin/nvcc.
[i 0728 14:02:45.144605 52 __init__.py:411] Found addr2line(2.30) at /usr/bin/addr2line.
[i 0728 14:02:45.286753 52 compiler.py:1011] cuda key:cu11.0.221_sm_86
[i 0728 14:02:45.745516 52 __init__.py:227] Total mem: 503.74GB, using 16 procs for compiling.
[i 0728 14:02:45.912619 52 jit_compiler.cc:28] Load cc_path: /usr/bin/g++
[i 0728 14:02:46.040928 52 init.cc:62] Found cuda archs: [86,]
[w 0728 14:02:46.120413 52 compiler.py:1384] CUDA arch(86)>80 will be backward-compatible
[i 0728 14:02:47.156876 52 __init__.py:411] Found mpicc(2.1.1) at /usr/bin/mpicc.
[i 0728 14:02:47.391991 08 compile_extern.py:339] Downloading cutt...
[i 0728 14:02:47.573554 08 compile_extern.py:352] installing cutt...
[i 0728 14:02:59.668120 36 compiler.py:34] Create cache dir: /user/HS400/ae01116/.cache/jittor/jt1.3.8/g++7.5.0/py3.9.19/Linux-4.18.0-4xae/AMDEPYC753232-x73/default/cu11.0.221_sm_86/cuda
Traceback (most recent call last):
Traceback (most recent call last):
  File "/mnt/fast/nobackup/users/ae01116/multi-modal-dissertation-uos/run_net.py", line 81, in <module>
    main()
  File "/mnt/fast/nobackup/users/ae01116/multi-modal-dissertation-uos/run_net.py", line 81, in <module>
    main()
  File "/mnt/fast/nobackup/users/ae01116/multi-modal-dissertation-uos/run_net.py", line 48, in main
    if "LOCAL_RANK" not in os.environ: # added by antoine
  File "/mnt/fast/nobackup/users/ae01116/multi-modal-dissertation-uos/run_net.py", line 48, in main
    if "LOCAL_RANK" not in os.environ: # added by antoine
NameError: name 'os' is not defined
NameError: name 'os' is not defined
Traceback (most recent call last):
  File "/mnt/fast/nobackup/users/ae01116/multi-modal-dissertation-uos/run_net.py", line 81, in <module>
    main()
  File "/mnt/fast/nobackup/users/ae01116/multi-modal-dissertation-uos/run_net.py", line 48, in main
    if "LOCAL_RANK" not in os.environ: # added by antoine
NameError: name 'os' is not defined
Traceback (most recent call last):
  File "/mnt/fast/nobackup/users/ae01116/multi-modal-dissertation-uos/run_net.py", line 81, in <module>
    main()
  File "/mnt/fast/nobackup/users/ae01116/multi-modal-dissertation-uos/run_net.py", line 48, in main
    if "LOCAL_RANK" not in os.environ: # added by antoine
NameError: name 'os' is not defined
ERROR:torch.distributed.elastic.multiprocessing.api:failed (exitcode: 1) local_rank: 0 (pid: 26) of binary: /mnt/fast/nobackup/scratch4weeks/ae01116/zegenv/bin/python
Traceback (most recent call last):
  File "/mnt/fast/nobackup/scratch4weeks/ae01116/zegenv/lib/python3.9/runpy.py", line 197, in _run_module_as_main
    return _run_code(code, main_globals, None,
  File "/mnt/fast/nobackup/scratch4weeks/ae01116/zegenv/lib/python3.9/runpy.py", line 87, in _run_code
    exec(code, run_globals)
  File "/mnt/fast/nobackup/scratch4weeks/ae01116/zegenv/lib/python3.9/site-packages/torch/distributed/launch.py", line 193, in <module>
    main()
  File "/mnt/fast/nobackup/scratch4weeks/ae01116/zegenv/lib/python3.9/site-packages/torch/distributed/launch.py", line 189, in main
    launch(args)
  File "/mnt/fast/nobackup/scratch4weeks/ae01116/zegenv/lib/python3.9/site-packages/torch/distributed/launch.py", line 174, in launch
    run(args)
  File "/mnt/fast/nobackup/scratch4weeks/ae01116/zegenv/lib/python3.9/site-packages/torch/distributed/run.py", line 710, in run
    elastic_launch(
  File "/mnt/fast/nobackup/scratch4weeks/ae01116/zegenv/lib/python3.9/site-packages/torch/distributed/launcher/api.py", line 131, in __call__
    return launch_agent(self._config, self._entrypoint, list(args))
  File "/mnt/fast/nobackup/scratch4weeks/ae01116/zegenv/lib/python3.9/site-packages/torch/distributed/launcher/api.py", line 259, in launch_agent
    raise ChildFailedError(
torch.distributed.elastic.multiprocessing.errors.ChildFailedError: 
============================================================
/mnt/fast/nobackup/users/ae01116/multi-modal-dissertation-uos/run_net.py FAILED
------------------------------------------------------------
Failures:
[1]:
  time      : 2024-07-28_14:03:22
  host      : ae01116-177938.0-aisurrey16.surrey.ac.uk
  rank      : 1 (local_rank: 1)
  exitcode  : 1 (pid: 27)
  error_file: <N/A>
  traceback : To enable traceback see: https://pytorch.org/docs/stable/elastic/errors.html
[2]:
  time      : 2024-07-28_14:03:22
  host      : ae01116-177938.0-aisurrey16.surrey.ac.uk
  rank      : 2 (local_rank: 2)
  exitcode  : 1 (pid: 28)
  error_file: <N/A>
  traceback : To enable traceback see: https://pytorch.org/docs/stable/elastic/errors.html
[3]:
  time      : 2024-07-28_14:03:22
  host      : ae01116-177938.0-aisurrey16.surrey.ac.uk
  rank      : 3 (local_rank: 3)
  exitcode  : 1 (pid: 29)
  error_file: <N/A>
  traceback : To enable traceback see: https://pytorch.org/docs/stable/elastic/errors.html
------------------------------------------------------------
Root Cause (first observed failure):
[0]:
  time      : 2024-07-28_14:03:22
  host      : ae01116-177938.0-aisurrey16.surrey.ac.uk
  rank      : 0 (local_rank: 0)
  exitcode  : 1 (pid: 26)
  error_file: <N/A>
  traceback : To enable traceback see: https://pytorch.org/docs/stable/elastic/errors.html
============================================================
