/mnt/fast/nobackup/scratch4weeks/ae01116/zegenv/lib/python3.9/site-packages/torch/distributed/launch.py:178: FutureWarning: The module torch.distributed.launch is deprecated
and will be removed in future. Use torchrun.
Note that --use_env is set by default in torchrun.
If your script expects `--local_rank` argument to be set, please
change it to read from `os.environ['LOCAL_RANK']` instead. See 
https://pytorch.org/docs/stable/distributed.html#launch-utility for 
further instructions

  warnings.warn(
[i 0728 13:41:17.444074 80 __init__.py:227] Total mem: 251.73GB, using 16 procs for compiling.
[i 0728 13:41:35.807247 80 jit_compiler.cc:28] Load cc_path: /usr/bin/g++
[i 0728 13:41:36.037362 80 init.cc:62] Found cuda archs: [75,]
[i 0728 13:41:37.045870 80 __init__.py:411] Found mpicc(2.1.1) at /usr/bin/mpicc.
[i 0728 13:41:37.123322 80 compiler.py:34] Create cache dir: /user/HS400/ae01116/.cache/jittor/jt1.3.8/g++7.5.0/py3.9.19/Linux-4.18.0-4xea/AMDEPYC750232-x2a/default/cu11.0.221_sm_75/custom_ops
[i 0728 13:41:38.902704 48 compiler.py:956] Jittor(1.3.8.5) src: /mnt/fast/nobackup/scratch4weeks/ae01116/zegenv/lib/python3.9/site-packages/jittor
[i 0728 13:41:38.908929 48 compiler.py:957] g++ at /usr/bin/g++(7.5.0)
[i 0728 13:41:38.908998 48 compiler.py:958] cache_path: /user/HS400/ae01116/.cache/jittor/jt1.3.8/g++7.5.0/py3.9.19/Linux-4.18.0-4xea/AMDEPYC750232-x2a/default
[i 0728 13:41:38.914190 48 __init__.py:411] Found nvcc(11.0.221) at /usr/local/cuda/bin/nvcc.
[i 0728 13:41:38.918658 48 __init__.py:411] Found addr2line(2.30) at /usr/bin/addr2line.
[i 0728 13:41:39.067999 48 compiler.py:1011] cuda key:cu11.0.221_sm_75
[i 0728 13:41:39.525978 48 __init__.py:227] Total mem: 251.73GB, using 16 procs for compiling.
[i 0728 13:41:39.698422 48 jit_compiler.cc:28] Load cc_path: /usr/bin/g++
[i 0728 13:41:39.827503 48 init.cc:62] Found cuda archs: [75,]
[i 0728 13:41:40.810488 48 __init__.py:411] Found mpicc(2.1.1) at /usr/bin/mpicc.
[i 0728 13:41:40.991606 76 compiler.py:956] Jittor(1.3.8.5) src: /mnt/fast/nobackup/scratch4weeks/ae01116/zegenv/lib/python3.9/site-packages/jittor
[i 0728 13:41:40.995751 76 compiler.py:957] g++ at /usr/bin/g++(7.5.0)
[i 0728 13:41:40.995818 76 compiler.py:958] cache_path: /user/HS400/ae01116/.cache/jittor/jt1.3.8/g++7.5.0/py3.9.19/Linux-4.18.0-4xea/AMDEPYC750232-x2a/default
[i 0728 13:41:41.000791 76 __init__.py:411] Found nvcc(11.0.221) at /usr/local/cuda/bin/nvcc.
[i 0728 13:41:41.005540 76 __init__.py:411] Found addr2line(2.30) at /usr/bin/addr2line.
[i 0728 13:41:41.142749 76 compiler.py:1011] cuda key:cu11.0.221_sm_75
[i 0728 13:41:41.588054 76 __init__.py:227] Total mem: 251.73GB, using 16 procs for compiling.
[i 0728 13:41:41.756962 76 jit_compiler.cc:28] Load cc_path: /usr/bin/g++
[i 0728 13:41:41.872408 76 init.cc:62] Found cuda archs: [75,]
[i 0728 13:41:42.850811 76 __init__.py:411] Found mpicc(2.1.1) at /usr/bin/mpicc.
[i 0728 13:41:42.958748 52 compiler.py:956] Jittor(1.3.8.5) src: /mnt/fast/nobackup/scratch4weeks/ae01116/zegenv/lib/python3.9/site-packages/jittor
[i 0728 13:41:42.978393 52 compiler.py:957] g++ at /usr/bin/g++(7.5.0)
[i 0728 13:41:42.978460 52 compiler.py:958] cache_path: /user/HS400/ae01116/.cache/jittor/jt1.3.8/g++7.5.0/py3.9.19/Linux-4.18.0-4xea/AMDEPYC750232-x2a/default
[i 0728 13:41:42.983087 52 __init__.py:411] Found nvcc(11.0.221) at /usr/local/cuda/bin/nvcc.
[i 0728 13:41:42.988288 52 __init__.py:411] Found addr2line(2.30) at /usr/bin/addr2line.
[i 0728 13:41:43.130076 52 compiler.py:1011] cuda key:cu11.0.221_sm_75
[i 0728 13:41:43.575466 52 __init__.py:227] Total mem: 251.73GB, using 16 procs for compiling.
[i 0728 13:41:43.742385 52 jit_compiler.cc:28] Load cc_path: /usr/bin/g++
[i 0728 13:41:43.872063 52 init.cc:62] Found cuda archs: [75,]
[i 0728 13:41:44.867048 52 __init__.py:411] Found mpicc(2.1.1) at /usr/bin/mpicc.
[i 0728 13:41:45.059210 80 compile_extern.py:339] Downloading cutt...
[i 0728 13:41:45.201888 80 compile_extern.py:352] installing cutt...
[i 0728 13:41:57.945948 52 compiler.py:34] Create cache dir: /user/HS400/ae01116/.cache/jittor/jt1.3.8/g++7.5.0/py3.9.19/Linux-4.18.0-4xea/AMDEPYC750232-x2a/default/cu11.0.221_sm_75/cuda
usage: run_net.py [-h] [--config-file FILE] [--task TASK] [--resume RESUME]
                  [--save-dir SAVE_DIR] [--no_cuda] [--efficient_val]
run_net.py: error: unrecognized arguments: --local_rank=3
usage: run_net.py [-h] [--config-file FILE] [--task TASK] [--resume RESUME]
                  [--save-dir SAVE_DIR] [--no_cuda] [--efficient_val]
run_net.py: error: unrecognized arguments: --local_rank=0
usage: run_net.py [-h] [--config-file FILE] [--task TASK] [--resume RESUME]
                  [--save-dir SAVE_DIR] [--no_cuda] [--efficient_val]
run_net.py: error: unrecognized arguments: --local_rank=1
usage: run_net.py [-h] [--config-file FILE] [--task TASK] [--resume RESUME]
                  [--save-dir SAVE_DIR] [--no_cuda] [--efficient_val]
run_net.py: error: unrecognized arguments: --local_rank=2
ERROR:torch.distributed.elastic.multiprocessing.api:failed (exitcode: 2) local_rank: 0 (pid: 26) of binary: /mnt/fast/nobackup/scratch4weeks/ae01116/zegenv/bin/python
Traceback (most recent call last):
  File "/mnt/fast/nobackup/scratch4weeks/ae01116/zegenv/lib/python3.9/runpy.py", line 197, in _run_module_as_main
    return _run_code(code, main_globals, None,
  File "/mnt/fast/nobackup/scratch4weeks/ae01116/zegenv/lib/python3.9/runpy.py", line 87, in _run_code
    exec(code, run_globals)
  File "/mnt/fast/nobackup/scratch4weeks/ae01116/zegenv/lib/python3.9/site-packages/torch/distributed/launch.py", line 193, in <module>
    main()
  File "/mnt/fast/nobackup/scratch4weeks/ae01116/zegenv/lib/python3.9/site-packages/torch/distributed/launch.py", line 189, in main
    launch(args)
  File "/mnt/fast/nobackup/scratch4weeks/ae01116/zegenv/lib/python3.9/site-packages/torch/distributed/launch.py", line 174, in launch
    run(args)
  File "/mnt/fast/nobackup/scratch4weeks/ae01116/zegenv/lib/python3.9/site-packages/torch/distributed/run.py", line 710, in run
    elastic_launch(
  File "/mnt/fast/nobackup/scratch4weeks/ae01116/zegenv/lib/python3.9/site-packages/torch/distributed/launcher/api.py", line 131, in __call__
    return launch_agent(self._config, self._entrypoint, list(args))
  File "/mnt/fast/nobackup/scratch4weeks/ae01116/zegenv/lib/python3.9/site-packages/torch/distributed/launcher/api.py", line 259, in launch_agent
    raise ChildFailedError(
torch.distributed.elastic.multiprocessing.errors.ChildFailedError: 
============================================================
/mnt/fast/nobackup/users/ae01116/multi-modal-dissertation-uos/run_net.py FAILED
------------------------------------------------------------
Failures:
[1]:
  time      : 2024-07-28_13:42:21
  host      : ae01116-177932.0-aisurrey08.surrey.ac.uk
  rank      : 1 (local_rank: 1)
  exitcode  : 2 (pid: 27)
  error_file: <N/A>
  traceback : To enable traceback see: https://pytorch.org/docs/stable/elastic/errors.html
[2]:
  time      : 2024-07-28_13:42:21
  host      : ae01116-177932.0-aisurrey08.surrey.ac.uk
  rank      : 2 (local_rank: 2)
  exitcode  : 2 (pid: 28)
  error_file: <N/A>
  traceback : To enable traceback see: https://pytorch.org/docs/stable/elastic/errors.html
[3]:
  time      : 2024-07-28_13:42:21
  host      : ae01116-177932.0-aisurrey08.surrey.ac.uk
  rank      : 3 (local_rank: 3)
  exitcode  : 2 (pid: 29)
  error_file: <N/A>
  traceback : To enable traceback see: https://pytorch.org/docs/stable/elastic/errors.html
------------------------------------------------------------
Root Cause (first observed failure):
[0]:
  time      : 2024-07-28_13:42:21
  host      : ae01116-177932.0-aisurrey08.surrey.ac.uk
  rank      : 0 (local_rank: 0)
  exitcode  : 2 (pid: 26)
  error_file: <N/A>
  traceback : To enable traceback see: https://pytorch.org/docs/stable/elastic/errors.html
============================================================
