/mnt/fast/nobackup/scratch4weeks/ae01116/zegenv/lib/python3.9/site-packages/torch/distributed/launch.py:178: FutureWarning: The module torch.distributed.launch is deprecated
and will be removed in future. Use torchrun.
Note that --use_env is set by default in torchrun.
If your script expects `--local_rank` argument to be set, please
change it to read from `os.environ['LOCAL_RANK']` instead. See 
https://pytorch.org/docs/stable/distributed.html#launch-utility for 
further instructions

  warnings.warn(
[i 0801 11:42:15.972422 88 __init__.py:227] Total mem: 503.74GB, using 16 procs for compiling.
[i 0801 11:42:35.190503 88 jit_compiler.cc:28] Load cc_path: /usr/bin/g++
[i 0801 11:42:35.382391 88 init.cc:62] Found cuda archs: [86,]
[w 0801 11:42:35.460672 88 compiler.py:1384] CUDA arch(86)>80 will be backward-compatible
[i 0801 11:42:36.839260 88 __init__.py:411] Found mpicc(2.1.1) at /usr/bin/mpicc.
[i 0801 11:42:36.930683 88 compiler.py:34] Create cache dir: /user/HS400/ae01116/.cache/jittor/jt1.3.8/g++7.5.0/py3.9.19/Linux-4.18.0-4x80/AMDEPYC753232-x73/default/cu11.0.221_sm_86/custom_ops
[i 0801 11:42:38.867644 76 compiler.py:956] Jittor(1.3.8.5) src: /mnt/fast/nobackup/scratch4weeks/ae01116/zegenv/lib/python3.9/site-packages/jittor
[i 0801 11:42:38.873189 76 compiler.py:957] g++ at /usr/bin/g++(7.5.0)
[i 0801 11:42:38.873263 76 compiler.py:958] cache_path: /user/HS400/ae01116/.cache/jittor/jt1.3.8/g++7.5.0/py3.9.19/Linux-4.18.0-4x80/AMDEPYC753232-x73/default
[i 0801 11:42:38.878234 76 __init__.py:411] Found nvcc(11.0.221) at /usr/local/cuda/bin/nvcc.
[i 0801 11:42:38.882947 76 __init__.py:411] Found addr2line(2.30) at /usr/bin/addr2line.
[i 0801 11:42:39.032377 76 compiler.py:1011] cuda key:cu11.0.221_sm_86
[i 0801 11:42:39.495026 76 __init__.py:227] Total mem: 503.74GB, using 16 procs for compiling.
[i 0801 11:42:39.678219 76 jit_compiler.cc:28] Load cc_path: /usr/bin/g++
[i 0801 11:42:39.811699 76 init.cc:62] Found cuda archs: [86,]
[w 0801 11:42:39.885095 76 compiler.py:1384] CUDA arch(86)>80 will be backward-compatible
[i 0801 11:42:41.166279 76 __init__.py:411] Found mpicc(2.1.1) at /usr/bin/mpicc.
[i 0801 11:42:41.305628 28 compiler.py:956] Jittor(1.3.8.5) src: /mnt/fast/nobackup/scratch4weeks/ae01116/zegenv/lib/python3.9/site-packages/jittor
[i 0801 11:42:41.311121 28 compiler.py:957] g++ at /usr/bin/g++(7.5.0)
[i 0801 11:42:41.311193 28 compiler.py:958] cache_path: /user/HS400/ae01116/.cache/jittor/jt1.3.8/g++7.5.0/py3.9.19/Linux-4.18.0-4x80/AMDEPYC753232-x73/default
[i 0801 11:42:41.316194 28 __init__.py:411] Found nvcc(11.0.221) at /usr/local/cuda/bin/nvcc.
[i 0801 11:42:41.320759 28 __init__.py:411] Found addr2line(2.30) at /usr/bin/addr2line.
[i 0801 11:42:41.456444 28 compiler.py:1011] cuda key:cu11.0.221_sm_86
[i 0801 11:42:41.926352 28 __init__.py:227] Total mem: 503.74GB, using 16 procs for compiling.
[i 0801 11:42:42.101706 28 jit_compiler.cc:28] Load cc_path: /usr/bin/g++
[i 0801 11:42:42.232517 28 init.cc:62] Found cuda archs: [86,]
[w 0801 11:42:42.305979 28 compiler.py:1384] CUDA arch(86)>80 will be backward-compatible
[i 0801 11:42:43.616765 28 __init__.py:411] Found mpicc(2.1.1) at /usr/bin/mpicc.
[i 0801 11:42:43.757245 88 compiler.py:956] Jittor(1.3.8.5) src: /mnt/fast/nobackup/scratch4weeks/ae01116/zegenv/lib/python3.9/site-packages/jittor
[i 0801 11:42:43.762907 88 compiler.py:957] g++ at /usr/bin/g++(7.5.0)
[i 0801 11:42:43.762980 88 compiler.py:958] cache_path: /user/HS400/ae01116/.cache/jittor/jt1.3.8/g++7.5.0/py3.9.19/Linux-4.18.0-4x80/AMDEPYC753232-x73/default
[i 0801 11:42:43.768589 88 __init__.py:411] Found nvcc(11.0.221) at /usr/local/cuda/bin/nvcc.
[i 0801 11:42:43.773722 88 __init__.py:411] Found addr2line(2.30) at /usr/bin/addr2line.
[i 0801 11:42:43.924788 88 compiler.py:1011] cuda key:cu11.0.221_sm_86
[i 0801 11:42:44.399927 88 __init__.py:227] Total mem: 503.74GB, using 16 procs for compiling.
[i 0801 11:42:44.583083 88 jit_compiler.cc:28] Load cc_path: /usr/bin/g++
[i 0801 11:42:44.719219 88 init.cc:62] Found cuda archs: [86,]
[w 0801 11:42:44.793987 88 compiler.py:1384] CUDA arch(86)>80 will be backward-compatible
[i 0801 11:42:45.978207 88 __init__.py:411] Found mpicc(2.1.1) at /usr/bin/mpicc.
[i 0801 11:42:46.218651 88 compile_extern.py:339] Downloading cutt...
[i 0801 11:42:46.387588 88 compile_extern.py:352] installing cutt...
[i 0801 11:42:59.091766 28 compiler.py:34] Create cache dir: /user/HS400/ae01116/.cache/jittor/jt1.3.8/g++7.5.0/py3.9.19/Linux-4.18.0-4x80/AMDEPYC753232-x73/default/cu11.0.221_sm_86/cuda
[i 0801 11:43:18.058694 88 cuda_flags.cc:49] CUDA enabled.
[i 0801 11:43:18.706235 28 cuda_flags.cc:49] CUDA enabled.
[i 0801 11:43:18.851780 76 cuda_flags.cc:49] CUDA enabled.
[i 0801 11:43:18.866103 88 cuda_flags.cc:49] CUDA enabled.

Compiling Operators(9/16) used: 3.44s eta: 2.68s Compiling Operators(13/16) used: 4.44s eta: 1.03s Compiling Operators(16/16) used: 5.44s eta:    0s 

Compiling Operators(3/4) used: 3.47s eta: 1.16s Compiling Operators(4/4) used: 4.47s eta:    0s 

Compiling Operators(1/2) used: 3.41s eta: 3.41s Compiling Operators(2/2) used: 4.41s eta:    0s 
/mnt/fast/nobackup/users/ae01116/multi-modal-dissertation-uos/jseg/models/losses/cross_entropy_loss.py:55: UserWarning: Default ``avg_non_ignore`` is False, if you would like to ignore the certain label and average loss over non-ignore labels, which is the same with Jittor official cross_entropy, set ``avg_non_ignore=True``.
  warnings.warn(
/mnt/fast/nobackup/users/ae01116/multi-modal-dissertation-uos/jseg/models/losses/cross_entropy_loss.py:55: UserWarning: Default ``avg_non_ignore`` is False, if you would like to ignore the certain label and average loss over non-ignore labels, which is the same with Jittor official cross_entropy, set ``avg_non_ignore=True``.
  warnings.warn(
/mnt/fast/nobackup/users/ae01116/multi-modal-dissertation-uos/jseg/models/losses/cross_entropy_loss.py:55: UserWarning: Default ``avg_non_ignore`` is False, if you would like to ignore the certain label and average loss over non-ignore labels, which is the same with Jittor official cross_entropy, set ``avg_non_ignore=True``.
  warnings.warn(
/mnt/fast/nobackup/users/ae01116/multi-modal-dissertation-uos/jseg/models/losses/cross_entropy_loss.py:55: UserWarning: Default ``avg_non_ignore`` is False, if you would like to ignore the certain label and average loss over non-ignore labels, which is the same with Jittor official cross_entropy, set ``avg_non_ignore=True``.
  warnings.warn(

Compiling Operators(6/6) used: 4.48s eta:    0s 

Compiling Operators(4/5) used: 3.32s eta: 0.831s Compiling Operators(5/5) used: 4.32s eta:    0s 

Compiling Operators(3/3) used: 4.33s eta:    0s 

Compiling Operators(3/3) used: 4.32s eta:    0s 
Traceback (most recent call last):
  File "/mnt/fast/nobackup/users/ae01116/multi-modal-dissertation-uos/jseg/utils/registry.py", line 33, in build_from_cfg
    module = obj_cls(**args)
  File "/mnt/fast/nobackup/users/ae01116/multi-modal-dissertation-uos/jseg/datasets/zero_voc12.py", line 31, in __init__
    super(ZeroPascalVOCDataset20, self).__init__(img_suffix='.jpg',
  File "/mnt/fast/nobackup/users/ae01116/multi-modal-dissertation-uos/jseg/datasets/custom.py", line 77, in __init__
    if not (self.ann_dir is None or osp.isabs(self.ann_dir)):
  File "/mnt/fast/nobackup/scratch4weeks/ae01116/zegenv/lib/python3.9/posixpath.py", line 62, in isabs
    s = os.fspath(s)
TypeError: expected str, bytes or os.PathLike object, not list

During handling of the above exception, another exception occurred:

Traceback (most recent call last):
  File "/mnt/fast/nobackup/users/ae01116/multi-modal-dissertation-uos/run_net.py", line 83, in <module>
    main()
  File "/mnt/fast/nobackup/users/ae01116/multi-modal-dissertation-uos/run_net.py", line 72, in main
    runner = Runner()
  File "/mnt/fast/nobackup/users/ae01116/multi-modal-dissertation-uos/jseg/runner/runner.py", line 51, in __init__
    self.train_dataset = build_from_cfg(cfg.dataset.train,
  File "/mnt/fast/nobackup/users/ae01116/multi-modal-dissertation-uos/jseg/utils/registry.py", line 37, in build_from_cfg
    raise TypeError(e)
TypeError: <class 'jseg.datasets.zero_voc12.ZeroPascalVOCDataset20'>.expected str, bytes or os.PathLike object, not list
Traceback (most recent call last):
  File "/mnt/fast/nobackup/users/ae01116/multi-modal-dissertation-uos/jseg/utils/registry.py", line 33, in build_from_cfg
    module = obj_cls(**args)
  File "/mnt/fast/nobackup/users/ae01116/multi-modal-dissertation-uos/jseg/datasets/zero_voc12.py", line 31, in __init__
    super(ZeroPascalVOCDataset20, self).__init__(img_suffix='.jpg',
  File "/mnt/fast/nobackup/users/ae01116/multi-modal-dissertation-uos/jseg/datasets/custom.py", line 77, in __init__
    if not (self.ann_dir is None or osp.isabs(self.ann_dir)):
  File "/mnt/fast/nobackup/scratch4weeks/ae01116/zegenv/lib/python3.9/posixpath.py", line 62, in isabs
    s = os.fspath(s)
TypeError: expected str, bytes or os.PathLike object, not list

During handling of the above exception, another exception occurred:

Traceback (most recent call last):
  File "/mnt/fast/nobackup/users/ae01116/multi-modal-dissertation-uos/run_net.py", line 83, in <module>
    main()
  File "/mnt/fast/nobackup/users/ae01116/multi-modal-dissertation-uos/run_net.py", line 72, in main
    runner = Runner()
  File "/mnt/fast/nobackup/users/ae01116/multi-modal-dissertation-uos/jseg/runner/runner.py", line 51, in __init__
    self.train_dataset = build_from_cfg(cfg.dataset.train,
  File "/mnt/fast/nobackup/users/ae01116/multi-modal-dissertation-uos/jseg/utils/registry.py", line 37, in build_from_cfg
    raise TypeError(e)
TypeError: <class 'jseg.datasets.zero_voc12.ZeroPascalVOCDataset20'>.expected str, bytes or os.PathLike object, not list
Traceback (most recent call last):
  File "/mnt/fast/nobackup/users/ae01116/multi-modal-dissertation-uos/jseg/utils/registry.py", line 33, in build_from_cfg
    module = obj_cls(**args)
  File "/mnt/fast/nobackup/users/ae01116/multi-modal-dissertation-uos/jseg/datasets/zero_voc12.py", line 31, in __init__
    super(ZeroPascalVOCDataset20, self).__init__(img_suffix='.jpg',
  File "/mnt/fast/nobackup/users/ae01116/multi-modal-dissertation-uos/jseg/datasets/custom.py", line 77, in __init__
    if not (self.ann_dir is None or osp.isabs(self.ann_dir)):
  File "/mnt/fast/nobackup/scratch4weeks/ae01116/zegenv/lib/python3.9/posixpath.py", line 62, in isabs
    s = os.fspath(s)
TypeError: expected str, bytes or os.PathLike object, not list

During handling of the above exception, another exception occurred:

Traceback (most recent call last):
  File "/mnt/fast/nobackup/users/ae01116/multi-modal-dissertation-uos/run_net.py", line 83, in <module>
    main()
  File "/mnt/fast/nobackup/users/ae01116/multi-modal-dissertation-uos/run_net.py", line 72, in main
    runner = Runner()
  File "/mnt/fast/nobackup/users/ae01116/multi-modal-dissertation-uos/jseg/runner/runner.py", line 51, in __init__
    self.train_dataset = build_from_cfg(cfg.dataset.train,
  File "/mnt/fast/nobackup/users/ae01116/multi-modal-dissertation-uos/jseg/utils/registry.py", line 37, in build_from_cfg
    raise TypeError(e)
TypeError: <class 'jseg.datasets.zero_voc12.ZeroPascalVOCDataset20'>.expected str, bytes or os.PathLike object, not list
Traceback (most recent call last):
  File "/mnt/fast/nobackup/users/ae01116/multi-modal-dissertation-uos/jseg/utils/registry.py", line 33, in build_from_cfg
    module = obj_cls(**args)
  File "/mnt/fast/nobackup/users/ae01116/multi-modal-dissertation-uos/jseg/datasets/zero_voc12.py", line 31, in __init__
    super(ZeroPascalVOCDataset20, self).__init__(img_suffix='.jpg',
  File "/mnt/fast/nobackup/users/ae01116/multi-modal-dissertation-uos/jseg/datasets/custom.py", line 77, in __init__
    if not (self.ann_dir is None or osp.isabs(self.ann_dir)):
  File "/mnt/fast/nobackup/scratch4weeks/ae01116/zegenv/lib/python3.9/posixpath.py", line 62, in isabs
    s = os.fspath(s)
TypeError: expected str, bytes or os.PathLike object, not list

During handling of the above exception, another exception occurred:

Traceback (most recent call last):
  File "/mnt/fast/nobackup/users/ae01116/multi-modal-dissertation-uos/run_net.py", line 83, in <module>
    main()
  File "/mnt/fast/nobackup/users/ae01116/multi-modal-dissertation-uos/run_net.py", line 72, in main
    runner = Runner()
  File "/mnt/fast/nobackup/users/ae01116/multi-modal-dissertation-uos/jseg/runner/runner.py", line 51, in __init__
    self.train_dataset = build_from_cfg(cfg.dataset.train,
  File "/mnt/fast/nobackup/users/ae01116/multi-modal-dissertation-uos/jseg/utils/registry.py", line 37, in build_from_cfg
    raise TypeError(e)
TypeError: <class 'jseg.datasets.zero_voc12.ZeroPascalVOCDataset20'>.expected str, bytes or os.PathLike object, not list
ERROR:torch.distributed.elastic.multiprocessing.api:failed (exitcode: 1) local_rank: 0 (pid: 26) of binary: /mnt/fast/nobackup/scratch4weeks/ae01116/zegenv/bin/python
Traceback (most recent call last):
  File "/mnt/fast/nobackup/scratch4weeks/ae01116/zegenv/lib/python3.9/runpy.py", line 197, in _run_module_as_main
    return _run_code(code, main_globals, None,
  File "/mnt/fast/nobackup/scratch4weeks/ae01116/zegenv/lib/python3.9/runpy.py", line 87, in _run_code
    exec(code, run_globals)
  File "/mnt/fast/nobackup/scratch4weeks/ae01116/zegenv/lib/python3.9/site-packages/torch/distributed/launch.py", line 193, in <module>
    main()
  File "/mnt/fast/nobackup/scratch4weeks/ae01116/zegenv/lib/python3.9/site-packages/torch/distributed/launch.py", line 189, in main
    launch(args)
  File "/mnt/fast/nobackup/scratch4weeks/ae01116/zegenv/lib/python3.9/site-packages/torch/distributed/launch.py", line 174, in launch
    run(args)
  File "/mnt/fast/nobackup/scratch4weeks/ae01116/zegenv/lib/python3.9/site-packages/torch/distributed/run.py", line 710, in run
    elastic_launch(
  File "/mnt/fast/nobackup/scratch4weeks/ae01116/zegenv/lib/python3.9/site-packages/torch/distributed/launcher/api.py", line 131, in __call__
    return launch_agent(self._config, self._entrypoint, list(args))
  File "/mnt/fast/nobackup/scratch4weeks/ae01116/zegenv/lib/python3.9/site-packages/torch/distributed/launcher/api.py", line 259, in launch_agent
    raise ChildFailedError(
torch.distributed.elastic.multiprocessing.errors.ChildFailedError: 
============================================================
/mnt/fast/nobackup/users/ae01116/multi-modal-dissertation-uos/run_net.py FAILED
------------------------------------------------------------
Failures:
[1]:
  time      : 2024-08-01_11:43:58
  host      : ae01116-178657.0-aisurrey19.surrey.ac.uk
  rank      : 1 (local_rank: 1)
  exitcode  : 1 (pid: 27)
  error_file: <N/A>
  traceback : To enable traceback see: https://pytorch.org/docs/stable/elastic/errors.html
[2]:
  time      : 2024-08-01_11:43:58
  host      : ae01116-178657.0-aisurrey19.surrey.ac.uk
  rank      : 2 (local_rank: 2)
  exitcode  : 1 (pid: 28)
  error_file: <N/A>
  traceback : To enable traceback see: https://pytorch.org/docs/stable/elastic/errors.html
[3]:
  time      : 2024-08-01_11:43:58
  host      : ae01116-178657.0-aisurrey19.surrey.ac.uk
  rank      : 3 (local_rank: 3)
  exitcode  : 1 (pid: 29)
  error_file: <N/A>
  traceback : To enable traceback see: https://pytorch.org/docs/stable/elastic/errors.html
------------------------------------------------------------
Root Cause (first observed failure):
[0]:
  time      : 2024-08-01_11:43:58
  host      : ae01116-178657.0-aisurrey19.surrey.ac.uk
  rank      : 0 (local_rank: 0)
  exitcode  : 1 (pid: 26)
  error_file: <N/A>
  traceback : To enable traceback see: https://pytorch.org/docs/stable/elastic/errors.html
============================================================
