/mnt/fast/nobackup/scratch4weeks/ae01116/zegenv/lib/python3.9/site-packages/torch/distributed/launch.py:178: FutureWarning: The module torch.distributed.launch is deprecated
and will be removed in future. Use torchrun.
Note that --use_env is set by default in torchrun.
If your script expects `--local_rank` argument to be set, please
change it to read from `os.environ['LOCAL_RANK']` instead. See 
https://pytorch.org/docs/stable/distributed.html#launch-utility for 
further instructions

  warnings.warn(
[i 0801 11:03:18.667660 48 __init__.py:227] Total mem: 503.74GB, using 16 procs for compiling.
[i 0801 11:03:37.444730 48 jit_compiler.cc:28] Load cc_path: /usr/bin/g++
[i 0801 11:03:37.662943 48 init.cc:62] Found cuda archs: [86,]
[w 0801 11:03:37.737226 48 compiler.py:1384] CUDA arch(86)>80 will be backward-compatible
[i 0801 11:03:38.934476 48 __init__.py:411] Found mpicc(2.1.1) at /usr/bin/mpicc.
[i 0801 11:03:39.020939 48 compiler.py:34] Create cache dir: /user/HS400/ae01116/.cache/jittor/jt1.3.8/g++7.5.0/py3.9.19/Linux-4.18.0-4xf5/AMDEPYC753232-x73/default/cu11.0.221_sm_86/custom_ops
[i 0801 11:03:40.891441 36 compiler.py:956] Jittor(1.3.8.5) src: /mnt/fast/nobackup/scratch4weeks/ae01116/zegenv/lib/python3.9/site-packages/jittor
[i 0801 11:03:40.896151 36 compiler.py:957] g++ at /usr/bin/g++(7.5.0)
[i 0801 11:03:40.896220 36 compiler.py:958] cache_path: /user/HS400/ae01116/.cache/jittor/jt1.3.8/g++7.5.0/py3.9.19/Linux-4.18.0-4xf5/AMDEPYC753232-x73/default
[i 0801 11:03:40.901024 36 __init__.py:411] Found nvcc(11.0.221) at /usr/local/cuda/bin/nvcc.
[i 0801 11:03:40.905745 36 __init__.py:411] Found addr2line(2.30) at /usr/bin/addr2line.
[i 0801 11:03:41.044691 36 compiler.py:1011] cuda key:cu11.0.221_sm_86
[i 0801 11:03:41.518042 36 __init__.py:227] Total mem: 503.74GB, using 16 procs for compiling.
[i 0801 11:03:41.707612 36 jit_compiler.cc:28] Load cc_path: /usr/bin/g++
[i 0801 11:03:41.845393 36 init.cc:62] Found cuda archs: [86,]
[w 0801 11:03:41.921095 36 compiler.py:1384] CUDA arch(86)>80 will be backward-compatible
[i 0801 11:03:43.158771 36 __init__.py:411] Found mpicc(2.1.1) at /usr/bin/mpicc.
[i 0801 11:03:43.389885 52 compiler.py:956] Jittor(1.3.8.5) src: /mnt/fast/nobackup/scratch4weeks/ae01116/zegenv/lib/python3.9/site-packages/jittor
[i 0801 11:03:43.394540 52 compiler.py:957] g++ at /usr/bin/g++(7.5.0)
[i 0801 11:03:43.394617 52 compiler.py:958] cache_path: /user/HS400/ae01116/.cache/jittor/jt1.3.8/g++7.5.0/py3.9.19/Linux-4.18.0-4xf5/AMDEPYC753232-x73/default
[i 0801 11:03:43.400666 52 __init__.py:411] Found nvcc(11.0.221) at /usr/local/cuda/bin/nvcc.
[i 0801 11:03:43.406597 52 __init__.py:411] Found addr2line(2.30) at /usr/bin/addr2line.
[i 0801 11:03:43.554293 52 compiler.py:1011] cuda key:cu11.0.221_sm_86
[i 0801 11:03:44.018783 52 __init__.py:227] Total mem: 503.74GB, using 16 procs for compiling.
[i 0801 11:03:44.189671 52 jit_compiler.cc:28] Load cc_path: /usr/bin/g++
[i 0801 11:03:44.318338 52 init.cc:62] Found cuda archs: [86,]
[w 0801 11:03:44.392060 52 compiler.py:1384] CUDA arch(86)>80 will be backward-compatible
[i 0801 11:03:45.612283 52 __init__.py:411] Found mpicc(2.1.1) at /usr/bin/mpicc.
[i 0801 11:03:45.758608 52 compiler.py:956] Jittor(1.3.8.5) src: /mnt/fast/nobackup/scratch4weeks/ae01116/zegenv/lib/python3.9/site-packages/jittor
[i 0801 11:03:45.763613 52 compiler.py:957] g++ at /usr/bin/g++(7.5.0)
[i 0801 11:03:45.763680 52 compiler.py:958] cache_path: /user/HS400/ae01116/.cache/jittor/jt1.3.8/g++7.5.0/py3.9.19/Linux-4.18.0-4xf5/AMDEPYC753232-x73/default
[i 0801 11:03:45.768127 52 __init__.py:411] Found nvcc(11.0.221) at /usr/local/cuda/bin/nvcc.
[i 0801 11:03:45.772798 52 __init__.py:411] Found addr2line(2.30) at /usr/bin/addr2line.
[i 0801 11:03:45.925425 52 compiler.py:1011] cuda key:cu11.0.221_sm_86
[i 0801 11:03:46.391531 52 __init__.py:227] Total mem: 503.74GB, using 16 procs for compiling.
[i 0801 11:03:46.571488 52 jit_compiler.cc:28] Load cc_path: /usr/bin/g++
[i 0801 11:03:46.699417 52 init.cc:62] Found cuda archs: [86,]
[w 0801 11:03:46.772919 52 compiler.py:1384] CUDA arch(86)>80 will be backward-compatible
[i 0801 11:03:48.039134 52 __init__.py:411] Found mpicc(2.1.1) at /usr/bin/mpicc.
[i 0801 11:03:48.359611 48 compile_extern.py:339] Downloading cutt...
[i 0801 11:03:48.557185 48 compile_extern.py:352] installing cutt...
[i 0801 11:04:01.662393 36 compiler.py:34] Create cache dir: /user/HS400/ae01116/.cache/jittor/jt1.3.8/g++7.5.0/py3.9.19/Linux-4.18.0-4xf5/AMDEPYC753232-x73/default/cu11.0.221_sm_86/cuda
[i 0801 11:04:20.994772 48 cuda_flags.cc:49] CUDA enabled.
[i 0801 11:04:21.107614 52 cuda_flags.cc:49] CUDA enabled.
[i 0801 11:04:21.753485 52 cuda_flags.cc:49] CUDA enabled.
[i 0801 11:04:21.848423 36 cuda_flags.cc:49] CUDA enabled.

Compiling Operators(1/16) used: 2.46s eta:   37s Compiling Operators(9/16) used: 3.46s eta: 2.69s Compiling Operators(13/16) used: 4.46s eta: 1.03s Compiling Operators(16/16) used: 5.47s eta:    0s 

Compiling Operators(3/4) used: 3.44s eta: 1.15s Compiling Operators(4/4) used: 4.44s eta:    0s 

Compiling Operators(1/2) used: 3.37s eta: 3.37s Compiling Operators(2/2) used: 4.37s eta:    0s 
/mnt/fast/nobackup/users/ae01116/multi-modal-dissertation-uos/jseg/models/losses/cross_entropy_loss.py:55: UserWarning: Default ``avg_non_ignore`` is False, if you would like to ignore the certain label and average loss over non-ignore labels, which is the same with Jittor official cross_entropy, set ``avg_non_ignore=True``.
  warnings.warn(
/mnt/fast/nobackup/users/ae01116/multi-modal-dissertation-uos/jseg/models/losses/cross_entropy_loss.py:55: UserWarning: Default ``avg_non_ignore`` is False, if you would like to ignore the certain label and average loss over non-ignore labels, which is the same with Jittor official cross_entropy, set ``avg_non_ignore=True``.
  warnings.warn(
/mnt/fast/nobackup/users/ae01116/multi-modal-dissertation-uos/jseg/models/losses/cross_entropy_loss.py:55: UserWarning: Default ``avg_non_ignore`` is False, if you would like to ignore the certain label and average loss over non-ignore labels, which is the same with Jittor official cross_entropy, set ``avg_non_ignore=True``.
  warnings.warn(
/mnt/fast/nobackup/users/ae01116/multi-modal-dissertation-uos/jseg/models/losses/cross_entropy_loss.py:55: UserWarning: Default ``avg_non_ignore`` is False, if you would like to ignore the certain label and average loss over non-ignore labels, which is the same with Jittor official cross_entropy, set ``avg_non_ignore=True``.
  warnings.warn(

Compiling Operators(1/6) used: 3.38s eta: 16.9s Compiling Operators(6/6) used: 4.38s eta:    0s 

Compiling Operators(4/5) used: 3.45s eta: 0.862s Compiling Operators(5/5) used: 4.45s eta:    0s 

Compiling Operators(3/3) used: 4.41s eta:    0s 

Compiling Operators(3/3) used: 4.39s eta:    0s 
Traceback (most recent call last):
  File "/mnt/fast/nobackup/users/ae01116/multi-modal-dissertation-uos/run_net.py", line 83, in <module>
    main()
  File "/mnt/fast/nobackup/users/ae01116/multi-modal-dissertation-uos/run_net.py", line 72, in main
    runner = Runner()
  File "/mnt/fast/nobackup/users/ae01116/multi-modal-dissertation-uos/jseg/runner/runner.py", line 51, in __init__
    self.train_dataset = build_from_cfg(cfg.dataset.train,
AttributeError: 'NoneType' object has no attribute 'train'
Traceback (most recent call last):
  File "/mnt/fast/nobackup/users/ae01116/multi-modal-dissertation-uos/run_net.py", line 83, in <module>
    main()
  File "/mnt/fast/nobackup/users/ae01116/multi-modal-dissertation-uos/run_net.py", line 72, in main
    runner = Runner()
  File "/mnt/fast/nobackup/users/ae01116/multi-modal-dissertation-uos/jseg/runner/runner.py", line 51, in __init__
    self.train_dataset = build_from_cfg(cfg.dataset.train,
AttributeError: 'NoneType' object has no attribute 'train'
Traceback (most recent call last):
  File "/mnt/fast/nobackup/users/ae01116/multi-modal-dissertation-uos/run_net.py", line 83, in <module>
    main()
  File "/mnt/fast/nobackup/users/ae01116/multi-modal-dissertation-uos/run_net.py", line 72, in main
    runner = Runner()
  File "/mnt/fast/nobackup/users/ae01116/multi-modal-dissertation-uos/jseg/runner/runner.py", line 51, in __init__
    self.train_dataset = build_from_cfg(cfg.dataset.train,
AttributeError: 'NoneType' object has no attribute 'train'
Traceback (most recent call last):
  File "/mnt/fast/nobackup/users/ae01116/multi-modal-dissertation-uos/run_net.py", line 83, in <module>
    main()
  File "/mnt/fast/nobackup/users/ae01116/multi-modal-dissertation-uos/run_net.py", line 72, in main
    runner = Runner()
  File "/mnt/fast/nobackup/users/ae01116/multi-modal-dissertation-uos/jseg/runner/runner.py", line 51, in __init__
    self.train_dataset = build_from_cfg(cfg.dataset.train,
AttributeError: 'NoneType' object has no attribute 'train'
ERROR:torch.distributed.elastic.multiprocessing.api:failed (exitcode: 1) local_rank: 0 (pid: 26) of binary: /mnt/fast/nobackup/scratch4weeks/ae01116/zegenv/bin/python
Traceback (most recent call last):
  File "/mnt/fast/nobackup/scratch4weeks/ae01116/zegenv/lib/python3.9/runpy.py", line 197, in _run_module_as_main
    return _run_code(code, main_globals, None,
  File "/mnt/fast/nobackup/scratch4weeks/ae01116/zegenv/lib/python3.9/runpy.py", line 87, in _run_code
    exec(code, run_globals)
  File "/mnt/fast/nobackup/scratch4weeks/ae01116/zegenv/lib/python3.9/site-packages/torch/distributed/launch.py", line 193, in <module>
    main()
  File "/mnt/fast/nobackup/scratch4weeks/ae01116/zegenv/lib/python3.9/site-packages/torch/distributed/launch.py", line 189, in main
    launch(args)
  File "/mnt/fast/nobackup/scratch4weeks/ae01116/zegenv/lib/python3.9/site-packages/torch/distributed/launch.py", line 174, in launch
    run(args)
  File "/mnt/fast/nobackup/scratch4weeks/ae01116/zegenv/lib/python3.9/site-packages/torch/distributed/run.py", line 710, in run
    elastic_launch(
  File "/mnt/fast/nobackup/scratch4weeks/ae01116/zegenv/lib/python3.9/site-packages/torch/distributed/launcher/api.py", line 131, in __call__
    return launch_agent(self._config, self._entrypoint, list(args))
  File "/mnt/fast/nobackup/scratch4weeks/ae01116/zegenv/lib/python3.9/site-packages/torch/distributed/launcher/api.py", line 259, in launch_agent
    raise ChildFailedError(
torch.distributed.elastic.multiprocessing.errors.ChildFailedError: 
============================================================
/mnt/fast/nobackup/users/ae01116/multi-modal-dissertation-uos/run_net.py FAILED
------------------------------------------------------------
Failures:
[1]:
  time      : 2024-08-01_11:05:01
  host      : ae01116-178644.0-aisurrey19.surrey.ac.uk
  rank      : 1 (local_rank: 1)
  exitcode  : 1 (pid: 27)
  error_file: <N/A>
  traceback : To enable traceback see: https://pytorch.org/docs/stable/elastic/errors.html
[2]:
  time      : 2024-08-01_11:05:01
  host      : ae01116-178644.0-aisurrey19.surrey.ac.uk
  rank      : 2 (local_rank: 2)
  exitcode  : 1 (pid: 28)
  error_file: <N/A>
  traceback : To enable traceback see: https://pytorch.org/docs/stable/elastic/errors.html
[3]:
  time      : 2024-08-01_11:05:01
  host      : ae01116-178644.0-aisurrey19.surrey.ac.uk
  rank      : 3 (local_rank: 3)
  exitcode  : 1 (pid: 29)
  error_file: <N/A>
  traceback : To enable traceback see: https://pytorch.org/docs/stable/elastic/errors.html
------------------------------------------------------------
Root Cause (first observed failure):
[0]:
  time      : 2024-08-01_11:05:01
  host      : ae01116-178644.0-aisurrey19.surrey.ac.uk
  rank      : 0 (local_rank: 0)
  exitcode  : 1 (pid: 26)
  error_file: <N/A>
  traceback : To enable traceback see: https://pytorch.org/docs/stable/elastic/errors.html
============================================================
