/mnt/fast/nobackup/scratch4weeks/ae01116/zegenv/lib/python3.9/site-packages/torch/distributed/launch.py:178: FutureWarning: The module torch.distributed.launch is deprecated
and will be removed in future. Use torchrun.
Note that --use_env is set by default in torchrun.
If your script expects `--local_rank` argument to be set, please
change it to read from `os.environ['LOCAL_RANK']` instead. See 
https://pytorch.org/docs/stable/distributed.html#launch-utility for 
further instructions

  warnings.warn(
[i 0801 11:32:14.564774 88 __init__.py:227] Total mem: 503.74GB, using 16 procs for compiling.
[i 0801 11:32:33.029960 88 jit_compiler.cc:28] Load cc_path: /usr/bin/g++
[i 0801 11:32:33.228276 88 init.cc:62] Found cuda archs: [86,]
[w 0801 11:32:33.310699 88 compiler.py:1384] CUDA arch(86)>80 will be backward-compatible
[i 0801 11:32:34.517851 88 __init__.py:411] Found mpicc(2.1.1) at /usr/bin/mpicc.
[i 0801 11:32:34.603249 88 compiler.py:34] Create cache dir: /user/HS400/ae01116/.cache/jittor/jt1.3.8/g++7.5.0/py3.9.19/Linux-4.18.0-4x34/AMDEPYC753232-x73/default/cu11.0.221_sm_86/custom_ops
[i 0801 11:32:36.452493 12 compiler.py:956] Jittor(1.3.8.5) src: /mnt/fast/nobackup/scratch4weeks/ae01116/zegenv/lib/python3.9/site-packages/jittor
[i 0801 11:32:36.457182 12 compiler.py:957] g++ at /usr/bin/g++(7.5.0)
[i 0801 11:32:36.457259 12 compiler.py:958] cache_path: /user/HS400/ae01116/.cache/jittor/jt1.3.8/g++7.5.0/py3.9.19/Linux-4.18.0-4x34/AMDEPYC753232-x73/default
[i 0801 11:32:36.462803 12 __init__.py:411] Found nvcc(11.0.221) at /usr/local/cuda/bin/nvcc.
[i 0801 11:32:36.468145 12 __init__.py:411] Found addr2line(2.30) at /usr/bin/addr2line.
[i 0801 11:32:36.603326 12 compiler.py:1011] cuda key:cu11.0.221_sm_86
[i 0801 11:32:37.066118 12 __init__.py:227] Total mem: 503.74GB, using 16 procs for compiling.
[i 0801 11:32:37.246215 12 jit_compiler.cc:28] Load cc_path: /usr/bin/g++
[i 0801 11:32:37.376871 12 init.cc:62] Found cuda archs: [86,]
[w 0801 11:32:37.451304 12 compiler.py:1384] CUDA arch(86)>80 will be backward-compatible
[i 0801 11:32:38.717021 12 __init__.py:411] Found mpicc(2.1.1) at /usr/bin/mpicc.
[i 0801 11:32:38.913284 80 compiler.py:956] Jittor(1.3.8.5) src: /mnt/fast/nobackup/scratch4weeks/ae01116/zegenv/lib/python3.9/site-packages/jittor
[i 0801 11:32:38.918482 80 compiler.py:957] g++ at /usr/bin/g++(7.5.0)
[i 0801 11:32:38.918582 80 compiler.py:958] cache_path: /user/HS400/ae01116/.cache/jittor/jt1.3.8/g++7.5.0/py3.9.19/Linux-4.18.0-4x34/AMDEPYC753232-x73/default
[i 0801 11:32:38.924374 80 __init__.py:411] Found nvcc(11.0.221) at /usr/local/cuda/bin/nvcc.
[i 0801 11:32:38.930237 80 __init__.py:411] Found addr2line(2.30) at /usr/bin/addr2line.
[i 0801 11:32:39.083037 80 compiler.py:1011] cuda key:cu11.0.221_sm_86
[i 0801 11:32:39.548791 80 __init__.py:227] Total mem: 503.74GB, using 16 procs for compiling.
[i 0801 11:32:39.719234 80 jit_compiler.cc:28] Load cc_path: /usr/bin/g++
[i 0801 11:32:39.849133 80 init.cc:62] Found cuda archs: [86,]
[w 0801 11:32:39.924126 80 compiler.py:1384] CUDA arch(86)>80 will be backward-compatible
[i 0801 11:32:41.359494 80 __init__.py:411] Found mpicc(2.1.1) at /usr/bin/mpicc.
[i 0801 11:32:41.505251 24 compiler.py:956] Jittor(1.3.8.5) src: /mnt/fast/nobackup/scratch4weeks/ae01116/zegenv/lib/python3.9/site-packages/jittor
[i 0801 11:32:41.510311 24 compiler.py:957] g++ at /usr/bin/g++(7.5.0)
[i 0801 11:32:41.510388 24 compiler.py:958] cache_path: /user/HS400/ae01116/.cache/jittor/jt1.3.8/g++7.5.0/py3.9.19/Linux-4.18.0-4x34/AMDEPYC753232-x73/default
[i 0801 11:32:41.515810 24 __init__.py:411] Found nvcc(11.0.221) at /usr/local/cuda/bin/nvcc.
[i 0801 11:32:41.521045 24 __init__.py:411] Found addr2line(2.30) at /usr/bin/addr2line.
[i 0801 11:32:41.655546 24 compiler.py:1011] cuda key:cu11.0.221_sm_86
[i 0801 11:32:42.120679 24 __init__.py:227] Total mem: 503.74GB, using 16 procs for compiling.
[i 0801 11:32:42.296061 24 jit_compiler.cc:28] Load cc_path: /usr/bin/g++
[i 0801 11:32:42.414746 24 init.cc:62] Found cuda archs: [86,]
[w 0801 11:32:42.490005 24 compiler.py:1384] CUDA arch(86)>80 will be backward-compatible
[i 0801 11:32:43.744907 24 __init__.py:411] Found mpicc(2.1.1) at /usr/bin/mpicc.
[i 0801 11:32:44.045242 88 compile_extern.py:339] Downloading cutt...
[i 0801 11:32:44.203657 88 compile_extern.py:352] installing cutt...
[i 0801 11:32:57.188473 12 compiler.py:34] Create cache dir: /user/HS400/ae01116/.cache/jittor/jt1.3.8/g++7.5.0/py3.9.19/Linux-4.18.0-4x34/AMDEPYC753232-x73/default/cu11.0.221_sm_86/cuda
[i 0801 11:33:15.706215 12 cuda_flags.cc:49] CUDA enabled.
[i 0801 11:33:15.750897 88 cuda_flags.cc:49] CUDA enabled.
[i 0801 11:33:15.805707 80 cuda_flags.cc:49] CUDA enabled.
[i 0801 11:33:16.729663 24 cuda_flags.cc:49] CUDA enabled.

Compiling Operators(1/16) used: 2.51s eta: 37.6s Compiling Operators(9/16) used: 3.51s eta: 2.73s Compiling Operators(16/16) used: 4.51s eta:    0s 

Compiling Operators(1/4) used: 2.41s eta: 7.22s Compiling Operators(3/4) used: 3.41s eta: 1.14s Compiling Operators(4/4) used: 4.41s eta:    0s 

Compiling Operators(1/2) used: 3.36s eta: 3.36s Compiling Operators(2/2) used: 4.36s eta:    0s 
/mnt/fast/nobackup/users/ae01116/multi-modal-dissertation-uos/jseg/models/losses/cross_entropy_loss.py:55: UserWarning: Default ``avg_non_ignore`` is False, if you would like to ignore the certain label and average loss over non-ignore labels, which is the same with Jittor official cross_entropy, set ``avg_non_ignore=True``.
  warnings.warn(
/mnt/fast/nobackup/users/ae01116/multi-modal-dissertation-uos/jseg/models/losses/cross_entropy_loss.py:55: UserWarning: Default ``avg_non_ignore`` is False, if you would like to ignore the certain label and average loss over non-ignore labels, which is the same with Jittor official cross_entropy, set ``avg_non_ignore=True``.
  warnings.warn(
/mnt/fast/nobackup/users/ae01116/multi-modal-dissertation-uos/jseg/models/losses/cross_entropy_loss.py:55: UserWarning: Default ``avg_non_ignore`` is False, if you would like to ignore the certain label and average loss over non-ignore labels, which is the same with Jittor official cross_entropy, set ``avg_non_ignore=True``.
  warnings.warn(
/mnt/fast/nobackup/users/ae01116/multi-modal-dissertation-uos/jseg/models/losses/cross_entropy_loss.py:55: UserWarning: Default ``avg_non_ignore`` is False, if you would like to ignore the certain label and average loss over non-ignore labels, which is the same with Jittor official cross_entropy, set ``avg_non_ignore=True``.
  warnings.warn(

Compiling Operators(6/6) used: 4.38s eta:    0s 

Compiling Operators(4/5) used: 3.41s eta: 0.853s Compiling Operators(5/5) used: 4.41s eta:    0s 

Compiling Operators(1/3) used: 3.38s eta: 6.77s Compiling Operators(3/3) used: 4.38s eta:    0s 

Compiling Operators(3/3) used: 4.37s eta:    0s 
Traceback (most recent call last):
  File "/mnt/fast/nobackup/users/ae01116/multi-modal-dissertation-uos/jseg/utils/registry.py", line 33, in build_from_cfg
    module = obj_cls(**args)
  File "/mnt/fast/nobackup/users/ae01116/multi-modal-dissertation-uos/jseg/datasets/zero_voc12.py", line 31, in __init__
    super(ZeroPascalVOCDataset20, self).__init__(img_suffix='.jpg',
  File "/mnt/fast/nobackup/users/ae01116/multi-modal-dissertation-uos/jseg/datasets/custom.py", line 77, in __init__
    if not (self.ann_dir is None or osp.isabs(self.ann_dir)):
  File "/mnt/fast/nobackup/scratch4weeks/ae01116/zegenv/lib/python3.9/posixpath.py", line 62, in isabs
    s = os.fspath(s)
TypeError: expected str, bytes or os.PathLike object, not list

During handling of the above exception, another exception occurred:

Traceback (most recent call last):
  File "/mnt/fast/nobackup/users/ae01116/multi-modal-dissertation-uos/run_net.py", line 83, in <module>
    main()
  File "/mnt/fast/nobackup/users/ae01116/multi-modal-dissertation-uos/run_net.py", line 72, in main
    runner = Runner()
  File "/mnt/fast/nobackup/users/ae01116/multi-modal-dissertation-uos/jseg/runner/runner.py", line 51, in __init__
    self.train_dataset = build_from_cfg(cfg.dataset.train,
  File "/mnt/fast/nobackup/users/ae01116/multi-modal-dissertation-uos/jseg/utils/registry.py", line 37, in build_from_cfg
    raise TypeError(e)
TypeError: <class 'jseg.datasets.zero_voc12.ZeroPascalVOCDataset20'>.expected str, bytes or os.PathLike object, not list
Traceback (most recent call last):
  File "/mnt/fast/nobackup/users/ae01116/multi-modal-dissertation-uos/jseg/utils/registry.py", line 33, in build_from_cfg
    module = obj_cls(**args)
  File "/mnt/fast/nobackup/users/ae01116/multi-modal-dissertation-uos/jseg/datasets/zero_voc12.py", line 31, in __init__
    super(ZeroPascalVOCDataset20, self).__init__(img_suffix='.jpg',
  File "/mnt/fast/nobackup/users/ae01116/multi-modal-dissertation-uos/jseg/datasets/custom.py", line 77, in __init__
    if not (self.ann_dir is None or osp.isabs(self.ann_dir)):
  File "/mnt/fast/nobackup/scratch4weeks/ae01116/zegenv/lib/python3.9/posixpath.py", line 62, in isabs
    s = os.fspath(s)
TypeError: expected str, bytes or os.PathLike object, not list

During handling of the above exception, another exception occurred:

Traceback (most recent call last):
  File "/mnt/fast/nobackup/users/ae01116/multi-modal-dissertation-uos/run_net.py", line 83, in <module>
    main()
  File "/mnt/fast/nobackup/users/ae01116/multi-modal-dissertation-uos/run_net.py", line 72, in main
    runner = Runner()
  File "/mnt/fast/nobackup/users/ae01116/multi-modal-dissertation-uos/jseg/runner/runner.py", line 51, in __init__
    self.train_dataset = build_from_cfg(cfg.dataset.train,
  File "/mnt/fast/nobackup/users/ae01116/multi-modal-dissertation-uos/jseg/utils/registry.py", line 37, in build_from_cfg
    raise TypeError(e)
TypeError: <class 'jseg.datasets.zero_voc12.ZeroPascalVOCDataset20'>.expected str, bytes or os.PathLike object, not list
Traceback (most recent call last):
  File "/mnt/fast/nobackup/users/ae01116/multi-modal-dissertation-uos/jseg/utils/registry.py", line 33, in build_from_cfg
    module = obj_cls(**args)
  File "/mnt/fast/nobackup/users/ae01116/multi-modal-dissertation-uos/jseg/datasets/zero_voc12.py", line 31, in __init__
    super(ZeroPascalVOCDataset20, self).__init__(img_suffix='.jpg',
  File "/mnt/fast/nobackup/users/ae01116/multi-modal-dissertation-uos/jseg/datasets/custom.py", line 77, in __init__
    if not (self.ann_dir is None or osp.isabs(self.ann_dir)):
  File "/mnt/fast/nobackup/scratch4weeks/ae01116/zegenv/lib/python3.9/posixpath.py", line 62, in isabs
    s = os.fspath(s)
TypeError: expected str, bytes or os.PathLike object, not list

During handling of the above exception, another exception occurred:

Traceback (most recent call last):
  File "/mnt/fast/nobackup/users/ae01116/multi-modal-dissertation-uos/run_net.py", line 83, in <module>
    main()
  File "/mnt/fast/nobackup/users/ae01116/multi-modal-dissertation-uos/run_net.py", line 72, in main
    runner = Runner()
  File "/mnt/fast/nobackup/users/ae01116/multi-modal-dissertation-uos/jseg/runner/runner.py", line 51, in __init__
    self.train_dataset = build_from_cfg(cfg.dataset.train,
  File "/mnt/fast/nobackup/users/ae01116/multi-modal-dissertation-uos/jseg/utils/registry.py", line 37, in build_from_cfg
    raise TypeError(e)
TypeError: <class 'jseg.datasets.zero_voc12.ZeroPascalVOCDataset20'>.expected str, bytes or os.PathLike object, not list
Traceback (most recent call last):
  File "/mnt/fast/nobackup/users/ae01116/multi-modal-dissertation-uos/jseg/utils/registry.py", line 33, in build_from_cfg
    module = obj_cls(**args)
  File "/mnt/fast/nobackup/users/ae01116/multi-modal-dissertation-uos/jseg/datasets/zero_voc12.py", line 31, in __init__
    super(ZeroPascalVOCDataset20, self).__init__(img_suffix='.jpg',
  File "/mnt/fast/nobackup/users/ae01116/multi-modal-dissertation-uos/jseg/datasets/custom.py", line 77, in __init__
    if not (self.ann_dir is None or osp.isabs(self.ann_dir)):
  File "/mnt/fast/nobackup/scratch4weeks/ae01116/zegenv/lib/python3.9/posixpath.py", line 62, in isabs
    s = os.fspath(s)
TypeError: expected str, bytes or os.PathLike object, not list

During handling of the above exception, another exception occurred:

Traceback (most recent call last):
  File "/mnt/fast/nobackup/users/ae01116/multi-modal-dissertation-uos/run_net.py", line 83, in <module>
    main()
  File "/mnt/fast/nobackup/users/ae01116/multi-modal-dissertation-uos/run_net.py", line 72, in main
    runner = Runner()
  File "/mnt/fast/nobackup/users/ae01116/multi-modal-dissertation-uos/jseg/runner/runner.py", line 51, in __init__
    self.train_dataset = build_from_cfg(cfg.dataset.train,
  File "/mnt/fast/nobackup/users/ae01116/multi-modal-dissertation-uos/jseg/utils/registry.py", line 37, in build_from_cfg
    raise TypeError(e)
TypeError: <class 'jseg.datasets.zero_voc12.ZeroPascalVOCDataset20'>.expected str, bytes or os.PathLike object, not list
WARNING:torch.distributed.elastic.multiprocessing.api:Sending process 27 closing signal SIGTERM
WARNING:torch.distributed.elastic.multiprocessing.api:Sending process 28 closing signal SIGTERM
WARNING:torch.distributed.elastic.multiprocessing.api:Sending process 29 closing signal SIGTERM
ERROR:torch.distributed.elastic.multiprocessing.api:failed (exitcode: 1) local_rank: 0 (pid: 26) of binary: /mnt/fast/nobackup/scratch4weeks/ae01116/zegenv/bin/python
Traceback (most recent call last):
  File "/mnt/fast/nobackup/scratch4weeks/ae01116/zegenv/lib/python3.9/runpy.py", line 197, in _run_module_as_main
    return _run_code(code, main_globals, None,
  File "/mnt/fast/nobackup/scratch4weeks/ae01116/zegenv/lib/python3.9/runpy.py", line 87, in _run_code
    exec(code, run_globals)
  File "/mnt/fast/nobackup/scratch4weeks/ae01116/zegenv/lib/python3.9/site-packages/torch/distributed/launch.py", line 193, in <module>
    main()
  File "/mnt/fast/nobackup/scratch4weeks/ae01116/zegenv/lib/python3.9/site-packages/torch/distributed/launch.py", line 189, in main
    launch(args)
  File "/mnt/fast/nobackup/scratch4weeks/ae01116/zegenv/lib/python3.9/site-packages/torch/distributed/launch.py", line 174, in launch
    run(args)
  File "/mnt/fast/nobackup/scratch4weeks/ae01116/zegenv/lib/python3.9/site-packages/torch/distributed/run.py", line 710, in run
    elastic_launch(
  File "/mnt/fast/nobackup/scratch4weeks/ae01116/zegenv/lib/python3.9/site-packages/torch/distributed/launcher/api.py", line 131, in __call__
    return launch_agent(self._config, self._entrypoint, list(args))
  File "/mnt/fast/nobackup/scratch4weeks/ae01116/zegenv/lib/python3.9/site-packages/torch/distributed/launcher/api.py", line 259, in launch_agent
    raise ChildFailedError(
torch.distributed.elastic.multiprocessing.errors.ChildFailedError: 
============================================================
/mnt/fast/nobackup/users/ae01116/multi-modal-dissertation-uos/run_net.py FAILED
------------------------------------------------------------
Failures:
  <NO_OTHER_FAILURES>
------------------------------------------------------------
Root Cause (first observed failure):
[0]:
  time      : 2024-08-01_11:33:52
  host      : ae01116-178652.0-aisurrey19.surrey.ac.uk
  rank      : 0 (local_rank: 0)
  exitcode  : 1 (pid: 26)
  error_file: <N/A>
  traceback : To enable traceback see: https://pytorch.org/docs/stable/elastic/errors.html
============================================================
